Workbook

Sheet Lisez-moi
A1: Prospects Bordeaux Métropole sans site web
A3: Mis à jour le | B3: 20 octobre 2026 (lot 1 : 19/10, lot 2 : 20/10)
A5: RÉSUMÉ
A6: Prospects sans site web (onglet Prospects) | B6: =COUNTA(Prospects!C2:C200) -> 51
A7: dont « Aucun site trouvé » | B7: =COUNTIF(Prospects!I2:I200,"Aucun trouvé") -> 47
A8: dont « Incertain » (à vérifier) | B8: =COUNTIF(Prospects!I2:I200,"Incertain") -> 4
A9: Entreprises écartées (site trouvé ou à éviter) | B9: =COUNTA('Écartées (site trouvé)'!A2:A200) -> 78
A10: Entreprises non vérifiées | B10: =COUNTA('Non vérifiées'!A2:A200) -> 29
A12: CRITÈRES DE SÉLECTION
A13: Zone | B13: Siège social dans Bordeaux Métropole (EPCI 243300316)
A14: Effectif | B14: Tranches INSEE 10-19 et 20-49 salariés (pas de tranche 10-30 dans les données publiques)
A15: Type | B15: PME indépendantes : au plus 3 établissements ouverts, catégorie PME
A16: Secteurs couverts | B16: BTP (section F), cabinets comptables et juridiques (69.10Z, 69.20Z). Le commerce n'a donné presque aucun résultat exploitable dans l'échantillon.
A18: MÉTHODE « SITE WEB »
A19: Comment | B19: Recherche web du nom + commune, en excluant les annuaires (societe.com, Pappers, PagesJaunes...). « Aucun trouvé » = seuls des annuaires apparaissent.
A20: Limite | B20: Une recherche peut rater un site mal référencé. Vérifie en 30 secondes avant d'appeler : une entreprise qui a déjà un site mais qui le trouve mauvais reste aussi un prospect.
A22: COMMENT UTILISER L'ONGLET PROSPECTS
A23: Colonnes jaunes | B23: À remplir par toi : Statut (liste déroulante), Date de contact, Interlocuteur, Notes
A24: Exemple de saisie | B24: Statut : RDV pris | Date : 05/11/2026 | Interlocuteur : gérant | Notes : stocke ses devis sur clé USB, intéressé par le partage avec les chefs de chantier
A26: SOURCES
A27: Données entreprises | B27: API Recherche d'entreprises (data.gouv.fr) : https://recherche-entreprises.api.gouv.fr
A28: Fiche de chaque entreprise | B28: Lien « Fiche officielle » vers annuaire-entreprises.data.gouv.fr
A29: Effectifs | B29: Tranche INSEE la plus récente disponible dans la base (souvent 2023 ou 2024) : l'effectif réel peut avoir changé

Sheet Prospects
A1: N° | B1: Lot | C1: Entreprise | D1: SIREN | E1: Secteur (code NAF) | F1: Effectif | G1: Commune | H1: Adresse du siège | I1: Site web | J1: Ce que j'ai trouvé | K1: Fiche officielle | L1: Statut | M1: Date de contact | N1: Interlocuteur | O1: Notes
A2: 1 | B2: 2 | C2: A2MA | D2: 531986610 | E2: Autres travaux d'installation (43.29B) | F2: 10-19 | G2: Cenon | H2: 4 RUE DU PROFESSEUR LANGEVIN 33150 CENON | I2: Aucun trouvé | J2: annuaires seulement (kompass, mappy, 118712, indeed) | K2: https://annuaire-entreprises.data.gouv.fr/entreprise/531986610 | L2: À contacter
A3: 2 | B3: 2 | C3: AECF (AECF) | D3: 451113153 | E3: Installation électrique (43.21A) | F3: 20-49 | G3: Villenave-D'Ornon | H3: 1 RUE MARC GAUTHIER 33140 VILLENAVE-D'ORNON | I3: Aucun trouvé | J3: annuaires seulement (mappy, kompass, 118712, omizi) | K3: https://annuaire-entreprises.data.gouv.fr/entreprise/451113153 | L3: À contacter
A4: 3 | B4: 1 | C4: AQUITAINE BOIS & COFFRAGE (A B C) | D4: 443242755 | E4: Menuiserie bois et PVC (43.32A) | F4: 10-19 | G4: Le Haillan | H4: 79 RUE DE LA MORANDIERE 33185 LE HAILLAN | I4: Aucun trouvé | J4: annuaires seulement (e-pro, aeroleads, infobel) | K4: https://annuaire-entreprises.data.gouv.fr/entreprise/443242755 | L4: À contacter
A5: 4 | B5: 2 | C5: BATMAX | D5: 901556381 | E5: Couverture (43.91B) | F5: 10-19 | G5: Bruges | H5: 10 AVENUE DE TERREFORT 33520 BRUGES | I5: Aucun trouvé | J5: annuaires seulement (doctrine, kompass) ; en croissance, recrute (France Travail, Glassdoor) | K5: https://annuaire-entreprises.data.gouv.fr/entreprise/901556381 | L5: À contacter
A6: 5 | B6: 1 | C6: BINGOL | D6: 519311252 | E6: Maçonnerie générale et gros œuvre (43.99C) | F6: 10-19 | G6: Cenon | H6: 16 CHEMIN DES BORIES 33150 CENON | I6: Aucun trouvé | J6: annuaires seulement (northdata, omizi, creditsafe) | K6: https://annuaire-entreprises.data.gouv.fr/entreprise/519311252 | L6: À contacter
A7: 6 | B7: 1 | C7: BT PIERRE | D7: 804308914 | E7: Maçonnerie générale et gros œuvre (43.99C) | F7: 10-19 | G7: Martignas-Sur-Jalle | H7: 72 C AVENUE MARTYRS DE LA RESISTANCE 33127 MARTIGNAS-SUR-JALLE | I7: Aucun trouvé | J7: annuaires seulement ; partenaire Stade Bordelais Rugby | K7: https://annuaire-entreprises.data.gouv.fr/entreprise/804308914 | L7: À contacter
A8: 7 | B8: 2 | C8: BYRITAN AQUITAINE | D8: 807851175 | E8: Revêtement des sols et des murs (43.33Z) | F8: 10-19 | G8: Cenon | H8: 3 RUE RENE MARTRENCHAR 33150 CENON | I8: Aucun trouvé | J8: annuaires seulement (revetement-sols.net, infonet) ; voisine du groupe Demonchy (rue René Martrenchar), lien à vérifier | K8: https://annuaire-entreprises.data.gouv.fr/entreprise/807851175 | L8: À contacter
A9: 8 | B9: 1 | C9: CEV CONSTRUCTION | D9: 892320888 | E9: Maçonnerie générale et gros œuvre (43.99C) | F9: 10-19 | G9: Cenon | H9: 12 RUE CONDORCET 33150 CENON | I9: Aucun trouvé | J9: annuaires seulement (mon-macon, travaux-publics.net) | K9: https://annuaire-entreprises.data.gouv.fr/entreprise/892320888 | L9: À contacter
A10: 9 | B10: 2 | C10: COULEUR HORIZON | D10: 842294530 | E10: Peinture et vitrerie (43.34Z) | F10: 10-19 | G10: Begles | H10: 386 B BOULEVARD JEAN-JACQUES BOSC 33130 BEGLES | I10: Aucun trouvé | J10: annuaires seulement (kompass, La Bonne Boîte, mon-peintre) | K10: https://annuaire-entreprises.data.gouv.fr/entreprise/842294530 | L10: À contacter
A11: 10 | B11: 1 | C11: CVC SOLUTIONS | D11: 841508880 | E11: Installation thermique et climatisation (43.22B) | F11: 10-19 | G11: Floirac | H11: 21 A RUE ARISTIDE BERGES 33270 FLOIRAC | I11: Aucun trouvé | J11: annuaires seulement (doctrine, chauffage-et-clim) ; airpac-cvc-33.fr est une autre entreprise | K11: https://annuaire-entreprises.data.gouv.fr/entreprise/841508880 | L11: À contacter
A12: 11 | B12: 2 | C12: DIF CONSTRUCTION | D12: 921899019 | E12: Maçonnerie générale et gros œuvre (43.99C) | F12: 10-19 | G12: Merignac | H12: CS 70101 26 AVENUE GUSTAVE EIFFEL 33700 MERIGNAC | I12: Aucun trouvé | J12: annuaires seulement (travaux.com, travaux-publics.net) ; même adresse qu'ISC Plâtrerie | K12: https://annuaire-entreprises.data.gouv.fr/entreprise/921899019 | L12: À contacter
A13: 12 | B13: 2 | C13: DOMINGUES PEINTURE REVETEMENT (DOMINGUES PEINTURE) (DPR) | D13: 513842823 | E13: Peinture et vitrerie (43.34Z) | F13: 10-19 | G13: Eysines | H13: 22 RUE DU 19 MARS 1962 33320 EYSINES | I13: Aucun trouvé | J13: annuaires seulement (annuaire mairie d'Eysines, mappy, kompass) ; 16 salariés | K13: https://annuaire-entreprises.data.gouv.fr/entreprise/513842823 | L13: À contacter
... A52: 51 | B52: 1 | C52: CABINET CEF | D52: 414973073 | E52: Activités comptables (69.20Z) | F52: 10-19 | G52: Merignac | H52: 9 IMPASSE JULES HETZEL 33700 MERIGNAC | I52: Incertain | J52: aucun résultat ; SIREN proche du Cabinet E. Queraux (même groupe probable) | K52: https://annuaire-entreprises.data.gouv.fr/entreprise/414973073 | L52: À contacter

Sheet Écartées (site trouvé)
A1: Entreprise | B1: SIREN | C1: Secteur (code NAF) | D1: Effectif | E1: Commune | F1: Site trouvé | G1: Remarque | H1: Domaine | I1: Messagerie | J1: Profil
A2: 2C EXPERTISES (2E) | B2: 753701002 | C2: Activités comptables (69.20Z) | D2: 10-19 | E2: Pessac | F2: http://2cexpertises.com/ | H2: 2cexpertises.com | I2: Non vérifié | J2: =IF(OR(I2="Pas de domaine",I2="Non vérifié"),"",IF(I2="Microsoft 365",1,2))
A3: ACER | B3: 432530830 | C3: Installation thermique et climatisation (43.22B) | D3: 10-19 | E3: Villenave-D'Ornon | F3: https://www.acer-creation.fr/ | G3: site « La société Acer » salles de bain Bordeaux (correspondance probable) | H3: acer-creation.fr | I3: Non vérifié | J3: =IF(OR(I3="Pas de domaine",I3="Non vérifié"),"",IF(I3="Microsoft 365",1,2))
A4: AFB 33 (AFB 33) | B4: 828960096 | C4: Peinture et vitrerie (43.34Z) | D4: 10-19 | E4: Merignac | F4: https://www.afb33-peinture.fr/ | H4: afb33-peinture.fr | I4: Non vérifié | J4: =IF(OR(I4="Pas de domaine",I4="Non vérifié"),"",IF(I4="Microsoft 365",1,2))
A5: AIR EAU ENERGIE GIRONDE (AEE33 AIR EAU ENERGIE GIRONDE) (AEE33) | B5: 509461612 | C5: Installation d'eau et de gaz (plomberie) (43.22A) | D5: 10-19 | E5: Merignac | F5: http://www.climatisation-chauffage-33.com/ | G5: site cité dans une fiche annuaire (non ouvert) | H5: climatisation-chauffage-33.com | I5: Non vérifié | J5: =IF(OR(I5="Pas de domaine",I5="Non vérifié"),"",IF(I5="Microsoft 365",1,2))
A6: AMENAGEMENT SENIORS HABITAT - ASH | B6: 815179692 | C6: Installation d'eau et de gaz (plomberie) (43.22A) | D6: 20-49 | E6: Begles | F6: https://www.asheurope.com/ | H6: asheurope.com | I6: Non vérifié | J6: =IF(OR(I6="Pas de domaine",I6="Non vérifié"),"",IF(I6="Microsoft 365",1,2))
A7: AQUITAINE ASCENSEURS | B7: 534766837 | C7: Autres travaux d'installation (43.29B) | D7: 10-19 | E7: Merignac | F7: https://www.aquitaine-asc.fr/ | H7: aquitaine-asc.fr | I7: Non vérifié | J7: =IF(OR(I7="Pas de domaine",I7="Non vérifié"),"",IF(I7="Microsoft 365",1,2))
A8: ARCHENERGIE | B8: 537649154 | C8: Travaux d'isolation (43.29A) | D8: 20-49 | E8: Le Haillan | F8: https://archenergie.fr/ | H8: archenergie.fr | I8: Non vérifié | J8: =IF(OR(I8="Pas de domaine",I8="Non vérifié"),"",IF(I8="Microsoft 365",1,2))
A9: ARTHEA | B9: 919648485 | C9: Travaux d'isolation (43.29A) | D9: 10-19 | E9: Merignac | F9: https://arthea-sas.fr/ | H9: arthea-sas.fr | I9: Non vérifié | J9: =IF(OR(I9="Pas de domaine",I9="Non vérifié"),"",IF(I9="Microsoft 365",1,2))
A10: ATELIER AND CO | B10: 803342948 | C10: Menuiserie bois et PVC (43.32A) | D10: 20-49 | E10: Pessac | F10: https://www.jsd-groupe.com/atelier-co/ | G10: groupe JSD | H10: jsd-groupe.com | I10: Non vérifié | J10: =IF(OR(I10="Pas de domaine",I10="Non vérifié"),"",IF(I10="Microsoft 365",1,2))
A11: ATLAS DEMOLITION 33 | B11: 513502906 | C11: Travaux de démolition (43.11Z) | D11: 10-19 | E11: Bouliac | F11: https://www.atlasdemolition.fr/ | H11: atlasdemolition.fr | I11: Non vérifié | J11: =IF(OR(I11="Pas de domaine",I11="Non vérifié"),"",IF(I11="Microsoft 365",1,2))
A12: B 2 C (B 2 C) | B12: 417580768 | C12: Menuiserie métallique et serrurerie (43.32B) | D12: 10-19 | E12: Martignas-Sur-Jalle | F12: https://sasb2c.com/ | H12: sasb2c.com | I12: Non vérifié | J12: =IF(OR(I12="Pas de domaine",I12="Non vérifié"),"",IF(I12="Microsoft 365",1,2))
A13: B'MIX | B13: 482078052 | C13: Menuiserie métallique et serrurerie (43.32B) | D13: 10-19 | E13: Begles | F13: https://www.bmix.fr/ | H13: bmix.fr | I13: Non vérifié | J13: =IF(OR(I13="Pas de domaine",I13="Non vérifié"),"",IF(I13="Microsoft 365",1,2))
A14: BAT S.M. SARL | B14: 388077349 | C14: Couverture (43.91B) | D14: 10-19 | E14: Cenon | F14: https://www.bat-sm.com/ | G14: groupe Demonchy | H14: bat-sm.com | I14: Non vérifié | J14: =IF(OR(I14="Pas de domaine",I14="Non vérifié"),"",IF(I14="Microsoft 365",1,2))
A15: BOIS CONCEPT M (B.C.M.) | B15: 800699175 | C15: Charpente (43.91A) | D15: 10-19 | E15: Merignac | F15: https://bois-concept-m.fr/ | H15: bois-concept-m.fr | I15: Non vérifié | J15: =IF(OR(I15="Pas de domaine",I15="Non vérifié"),"",IF(I15="Microsoft 365",1,2))
A16: BOMAS CONSTRUCTION | B16: 444051668 | C16: Maçonnerie générale et gros œuvre (43.99C) | D16: 20-49 | E16: Ambares-Et-Lagrave | F16: http://www.bomas-construction.com/ | H16: bomas-construction.com | I16: Non vérifié | J16: =IF(OR(I16="Pas de domaine",I16="Non vérifié"),"",IF(I16="Microsoft 365",1,2))
A17: BONNET ETANCHEITE | B17: 521423517 | C17: Étanchéité (43.99A) | D17: 10-19 | E17: Cenon | F17: https://www.bonnet-etancheite.com/ | H17: bonnet-etancheite.com | I17: Non vérifié | J17: =IF(OR(I17="Pas de domaine",I17="Non vérifié"),"",IF(I17="Microsoft 365",1,2))
A18: BORDEAUX FERMETURES | B18: 442566709 | C18: Menuiserie bois et PVC (43.32A) | D18: 10-19 | E18: Begles | F18: https://www.bordeaux-fermeture.fr/ | H18: bordeaux-fermeture.fr | I18: Non vérifié | J18: =IF(OR(I18="Pas de domaine",I18="Non vérifié"),"",IF(I18="Microsoft 365",1,2))
A19: CABINET COMBY | B19: 511830812 | C19: Activités comptables (69.20Z) | D19: 10-19 | E19: Bordeaux | F19: https://www.comby.fr/ | H19: comby.fr | I19: Non vérifié | J19: =IF(OR(I19="Pas de domaine",I19="Non vérifié"),"",IF(I19="Microsoft 365",1,2))
A20: CABINET JG BEZ SA | B20: 301277257 | C20: Activités comptables (69.20Z) | D20: 10-19 | E20: Merignac | F20: https://expertys-metropole.com/ | G20: site du groupe Expertys | H20: expertys-metropole.com | I20: Non vérifié | J20: =IF(OR(I20="Pas de domaine",I20="Non vérifié"),"",IF(I20="Microsoft 365",1,2))
A21: CABINET STEPHANE MANDIN SARL | B21: 444723563 | C21: Activités comptables (69.20Z) | D21: 10-19 | E21: Merignac | F21: https://www.cabinet-mandin.fr/ | H21: cabinet-mandin.fr | I21: Non vérifié | J21: =IF(OR(I21="Pas de domaine",I21="Non vérifié"),"",IF(I21="Microsoft 365",1,2))
A22: CONSTRUCTIONS JOSES (CONSTRUCTIONS JOSES) | B22: 794148080 | C22: Maçonnerie générale et gros œuvre (43.99C) | D22: 10-19 | E22: Merignac | F22: http://construcoesjoses.com/ | G22: site du groupe (agence Mérignac) | H22: construcoesjoses.com | I22: Non vérifié | J22: =IF(OR(I22="Pas de domaine",I22="Non vérifié"),"",IF(I22="Microsoft 365",1,2))
A23: CULTURE COMPTABLE | B23: 822343018 | C23: Activités comptables (69.20Z) | D23: 20-49 | E23: Bordeaux | F23: https://www.culturecomptable.com/ | H23: culturecomptable.com | I23: Non vérifié | J23: =IF(OR(I23="Pas de domaine",I23="Non vérifié"),"",IF(I23="Microsoft 365",1,2))
A24: ED ENERGY | B24: 810246470 | C24: Installation d'eau et de gaz (plomberie) (43.22A) | D24: 10-19 | E24: Merignac | F24: https://ed-energy.fr/ | H24: ed-energy.fr | I24: Non vérifié | J24: =IF(OR(I24="Pas de domaine",I24="Non vérifié"),"",IF(I24="Microsoft 365",1,2))
A25: ELECTROGAZ | B25: 515137404 | C25: Installation thermique et climatisation (43.22B) | D25: 20-49 | E25: Merignac | F25: https://electro-gaz.fr/ | H25: electro-gaz.fr | I25: Non vérifié | J25: =IF(OR(I25="Pas de domaine",I25="Non vérifié"),"",IF(I25="Microsoft 365",1,2))
A26: ENTREPRISE BAROUMES | B26: 439701525 | C26: Installation d'eau et de gaz (plomberie) (43.22A) | D26: 20-49 | E26: Villenave-D'Ornon | F26: https://baroumes.fr/ | H26: baroumes.fr | I26: Non vérifié | J26: =IF(OR(I26="Pas de domaine",I26="Non vérifié"),"",IF(I26="Microsoft 365",1,2))
A27: ETABLISSEMENTS DUPHIL ET CIE | B27: 467200549 | C27: Agencement de lieux de vente (43.32C) | D27: 10-19 | E27: Bordeaux | F27: https://www.lesateliersduphil.net/ | H27: lesateliersduphil.net | I27: Non vérifié | J27: =IF(OR(I27="Pas de domaine",I27="Non vérifié"),"",IF(I27="Microsoft 365",1,2))
A28: ETABLISSEMENTS MICHEL ALLYRE | B28: 344916812 | C28: Couverture (43.91B) | D28: 20-49 | E28: Le Haillan | F28: https://allyre.com/ | H28: allyre.com | I28: Non vérifié | J28: =IF(OR(I28="Pas de domaine",I28="Non vérifié"),"",IF(I28="Microsoft 365",1,2))
A29: EURL ESPACES COULEURS | B29: 421798042 | C29: Peinture et vitrerie (43.34Z) | D29: 20-49 | E29: Ambares-Et-Lagrave | F29: https://www.espaces-couleurs.fr/ | H29: espaces-couleurs.fr | I29: Non vérifié | J29: =IF(OR(I29="Pas de domaine",I29="Non vérifié"),"",IF(I29="Microsoft 365",1,2))
A30: EVEAA | B30: 888202017 | C30: Installation thermique et climatisation (43.22B) | D30: 20-49 | E30: Pessac | F30: https://www.cimea.fr/eveaa/ | G30: page sur le site du groupe CIMEA | H30: cimea.fr | I30: Non vérifié | J30: =IF(OR(I30="Pas de domaine",I30="Non vérifié"),"",IF(I30="Microsoft 365",1,2))
A31: FRADIN | B31: 351793161 | C31: Promotion immobilière de logements (41.10A) | D31: 10-19 | E31: Lormont | F31: https://www.fradin-promotion.fr/ | G31: site du groupe Fradin | H31: fradin-promotion.fr | I31: Non vérifié | J31: =IF(OR(I31="Pas de domaine",I31="Non vérifié"),"",IF(I31="Microsoft 365",1,2))
A32: GARANCE COUVERTURE | B32: 811826304 | C32: Couverture (43.91B) | D32: 20-49 | E32: Le Bouscat | F32: https://www.garance-couverture.fr/ | H32: garance-couverture.fr | I32: Non vérifié | J32: =IF(OR(I32="Pas de domaine",I32="Non vérifié"),"",IF(I32="Microsoft 365",1,2))
A33: GERFA SUD OUEST | B33: 490248879 | C33: Étanchéité (43.99A) | D33: 10-19 | E33: Merignac | F33: https://www.gerfa.fr/ | G33: site du groupe GERFA | H33: gerfa.fr | I33: Non vérifié | J33: =IF(OR(I33="Pas de domaine",I33="Non vérifié"),"",IF(I33="Microsoft 365",1,2))
A34: GROUPE DONITIAN | B34: 379679152 | C34: Location de matériel de construction avec opérateur (43.99E) | D34: 10-19 | E34: Lormont | F34: — | G34: ÉCARTÉE : fiche dans la dataroom d'une étude de mandataire judiciaire (etude-mequinion.eu) : entreprise probablement en procédure, à écarter | H34: — | I34: Pas de domaine | J34: =IF(OR(I34="Pas de domaine",I34="Non vérifié"),"",IF(I34="Microsoft 365",1,2))
A35: HARRIBEY CONSTRUCTIONS | B35: 413657164 | C35: Construction d'autres bâtiments (41.20B) | D35: 20-49 | E35: Merignac | F35: https://harribeyconstructions.fr/ | H35: harribeyconstructions.fr | I35: Non vérifié | J35: =IF(OR(I35="Pas de domaine",I35="Non vérifié"),"",IF(I35="Microsoft 365",1,2))
A36: HDMS | B36: 830017521 | C36: Menuiserie métallique et serrurerie (43.32B) | D36: 10-19 | E36: Merignac | F36: https://hdms33.fr/ | H36: hdms33.fr | I36: Non vérifié | J36: =IF(OR(I36="Pas de domaine",I36="Non vérifié"),"",IF(I36="Microsoft 365",1,2))
A37: ILEX AQUITAINE | B37: 810026302 | C37: Autres travaux d'installation (43.29B) | D37: 10-19 | E37: Martignas-Sur-Jalle | F37: https://ilexascenseurs.com/agences/ilex-aquitaine/ | G37: agence du réseau ILEX | H37: ilexascenseurs.com | I37: Non vérifié | J37: =IF(OR(I37="Pas de domaine",I37="Non vérifié"),"",IF(I37="Microsoft 365",1,2))
A38: INGENIERIE CONCEPT - AMENAGEMENTS INTERIEURS (IC-AI) | B38: 534246038 | C38: Installation électrique (43.21A) | D38: 10-19 | E38: Cenon | F38: https://www.groupedemonchy.fr/ | G38: filiale du groupe Demonchy (cité sur le site du groupe) | H38: groupedemonchy.fr | I38: Non vérifié | J38: =IF(OR(I38="Pas de domaine",I38="Non vérifié"),"",IF(I38="Microsoft 365",1,2))
A39: JSD ENTREPRISE | B39: 410195853 | C39: Maçonnerie générale et gros œuvre (43.99C) | D39: 20-49 | E39: Pessac | F39: https://www.jsd-groupe.com/jsd-entreprise/ | H39: jsd-groupe.com | I39: Non vérifié | J39: =IF(OR(I39="Pas de domaine",I39="Non vérifié"),"",IF(I39="Microsoft 365",1,2))
A40: JULIEN LAVOINE | B40: 753553114 | C40: Charpente (43.91A) | D40: 20-49 | E40: Merignac | F40: https://julienlavoinecharpentiers.com/ | H40: julienlavoinecharpentiers.com | I40: Non vérifié | J40: =IF(OR(I40="Pas de domaine",I40="Non vérifié"),"",IF(I40="Microsoft 365",1,2))
...

Sheet Non vérifiées
A1: Entreprise | B1: SIREN | C1: Secteur (code NAF) | D1: Effectif | E1: Commune | F1: Fiche officielle | G1: Pourquoi non vérifiée
A2: ADRIEN DUTOUR, CYRILLE DE RUL, CHRISTOPHE LACOSTE, SANDRINE PAGES, AUDREY PELLET-LAVEVE, GREGORY DANDIEU MELODIE REMIA E | B2: 327234076 | C2: Activités juridiques (69.10Z) | D2: 20-49 | E2: Bordeaux | F2: https://annuaire-entreprises.data.gouv.fr/entreprise/327234076 | G2: Profession réglementée, très souvent équipée d'un site : non vérifiée
A3: ALTHESIA (PRESERVATION DU PATRIMOINE) | B3: 520078320 | C3: Travaux d'isolation (43.29A) | D3: 10-19 | E3: Merignac | F3: https://annuaire-entreprises.data.gouv.fr/entreprise/520078320 | G3: Non vérifiée : objectif de 50 atteint avant. Réserve pour un prochain lot
A4: ALTUM | B4: 301572442 | C4: Activités comptables (69.20Z) | D4: 20-49 | E4: Bordeaux | F4: https://annuaire-entreprises.data.gouv.fr/entreprise/301572442 | G4: Profession réglementée, très souvent équipée d'un site : non vérifiée
A5: AQUI TELECOMS | B5: 889282984 | C5: Activités des sièges sociaux (70.10Z) | D5: 10-19 | E5: Bordeaux | F5: https://annuaire-entreprises.data.gouv.fr/entreprise/889282984 | G5: Non vérifiée : objectif de 50 atteint avant. Réserve pour un prochain lot
A6: AQUITAINE HOSPITALITY | B6: 433116191 | C6: Promotion immobilière de logements (41.10A) | D6: 10-19 | E6: Talence | F6: https://annuaire-entreprises.data.gouv.fr/entreprise/433116191 | G6: Non vérifiée : objectif de 50 atteint avant. Réserve pour un prochain lot
A7: ARS (ARS) | B7: 489686386 | C7: Revêtement des sols et des murs (43.33Z) | D7: 10-19 | E7: Talence | F7: https://annuaire-entreprises.data.gouv.fr/entreprise/489686386 | G7: Non vérifiée : objectif de 50 atteint avant. Réserve pour un prochain lot
A8: ASA FEDERATION GIRONDINE DES ASA DE DFCI | B8: 293301503 | C8: Autres travaux de génie civil (42.99Z) | D8: 10-19 | E8: Bordeaux | F8: https://annuaire-entreprises.data.gouv.fr/entreprise/293301503 | G8: Organisme public (association syndicale), hors cible
A9: ASSOCIATION EIPF | B9: 332303999 | C9: Peinture et vitrerie (43.34Z) | D9: 10-19 | E9: Bordeaux | F9: https://annuaire-entreprises.data.gouv.fr/entreprise/332303999 | G9: Association, hors cible
A10: ATOUT' STORES | B10: 815150529 | C10: Menuiserie métallique et serrurerie (43.32B) | D10: 10-19 | E10: Merignac | F10: https://annuaire-entreprises.data.gouv.fr/entreprise/815150529 | G10: Non vérifiée : objectif de 50 atteint avant. Réserve pour un prochain lot
A11: AUDIAL EXPERTISE ET CONSEIL (AUDIAL) | B11: 458201738 | C11: Activités comptables (69.20Z) | D11: 20-49 | E11: Merignac | F11: https://annuaire-entreprises.data.gouv.fr/entreprise/458201738 | G11: Profession réglementée, très souvent équipée d'un site : non vérifiée
A12: BARBE SIS | B12: 340113398 | C12: Couverture (43.91B) | D12: 10-19 | E12: Bordeaux | F12: https://annuaire-entreprises.data.gouv.fr/entreprise/340113398 | G12: Non vérifiée : objectif de 50 atteint avant. Réserve pour un prochain lot
... A30: YAIGRE NOTAIRES ASSOCIES | B30: 318123155 | C30: Activités juridiques (69.10Z) | D30: 20-49 | E30: Bordeaux | F30: https://annuaire-entreprises.data.gouv.fr/entreprise/318123155 | G30: Profession réglementée, très souvent équipée d'un site : non vérifiée
